Workbook

Sheet F&I Log
T1: Total VSC | U1: Triton Protect Advantage | V1: Total MAINTENANCE | W1: Triton Image Guard | X1: 3 For 1 | Y1: Triton Drive 360 | Z1: Lease Wear Care | AA1: Lease EWT | AB1: Other Aftermarket
A2: Contract Date | B2: VIN | C2: Year | D2: Make | E2: Model | F2: Vehicle Type | G2: Contract Type | H2: Customer | I2: Sale Type | J2: First Name | K2: Last Name | L2: Address1 | M2: City | N2: State | O2: Zip | P2: Email Address | Q2: Home Phone | R2: Work Phone | S2: Cell Phone | T2: Income | U2: Income | V2: Income | W2: Income | X2: Income | Y2: Income | Z2: Income | AA2: Income | AB2: Income
A3: 2025-01-02 | B3: 1FMCU9MN7RUB00853 | C3: 2024 | D3: FORD | E3: ESCAPE | F3: Truck | G3: Retail | H3: BILL WISE'S EXCAVATING INC | I3: Conventional | K3: BILL WISE'S EXCAVATING INC | L3: 944 JOLLYTOWN RD | M3: NEW FREEPORT | N3: PA | O3: 15352-1574 | Q3: 724-451-8175 | T3: 600 | U3: 0 | V3: 0 | W3: 0 | X3: 0 | Y3: 0 | Z3: 0 | AA3: 0 | AB3: 0
A4: 2025-01-02 | B4: 1FMUK8KH9SGA60104 | C4: 2025 | D4: FORD | E4: EXPLORER | F4: Truck | G4: Retail | H4: HAYES,DEBORAH | I4: Conventional | J4: DEBORAH | K4: HAYES | L4: 106 GERTRUDE DR | M4: CHALFONT | N4: PA | O4: 18914 | P4: DHAYES1020@GMAIL.COM | Q4: 215-272-2654 | S4: 215-272-2654 | T4: 1801 | U4: 0 | V4: 405 | W4: 0 | X4: 0 | Y4: 0 | Z4: 0 | AA4: 0 | AB4: 0
A5: 2025-01-02 | B5: 1FMUK8DH1SGA43276 | C5: 2025 | D5: FORD | E5: EXPLORER | F5: Truck | G5: Retail | H5: BASZNIANIN,DARIUSZ | I5: Conventional | J5: DARIUSZ | K5: BASZNIANIN | L5: 1469 TARLETON PL | M5: WARMINSTER | N5: PA | O5: 18974 | P5: DBDARlUSZ@GMAIL.COM | Q5: 215-403-1125 | S5: 215-403-1124 | T5: 0 | U5: 0 | V5: 0 | W5: 0 | X5: 0 | Y5: 0 | Z5: 0 | AA5: 0 | AB5: 0
A6: 2025-01-02 | B6: 3FMTK3SU8RMA43287 | C6: 2024 | D6: FORD | E6: MUSTME | F6: Truck | G6: Retail | H6: POIRIER,LUC STEPHANE | I6: Conventional | J6: LUC | K6: POIRIER | L6: 113 TELEGRAPH RD | M6: PERKASIE | N6: PA | O6: 18944-2644 | P6: LUC.S.POIRIER@GMAIL.COM | Q6: 612-434-4486 | S6: 612-434-4486 | T6: 1280 | U6: 0 | V6: 405 | W6: 0 | X6: 0 | Y6: 653 | Z6: 0 | AA6: 0 | AB6: 0
A7: 2025-01-02 | B7: 3FMTK3SU3RMA52687 | C7: 2024 | D7: FORD | E7: MUSTME | F7: Truck | G7: Retail | H7: THALJI,REEMA KHALID | I7: Conventional | J7: REEMA | K7: THALJI | L7: 608 LAKEVIEW CT | M7: KNG OF PRUSSA | N7: PA | O7: 19406-1542 | P7: REEMA.THALJI@GMAIL.COM | Q7: 734-904-5470 | S7: 734-904-5470 | T7: 0 | U7: 0 | V7: 0 | W7: 0 | X7: 0 | Y7: 0 | Z7: 0 | AA7: 0 | AB7: 0
A8: 2025-01-02 | B8: 1FMCU9MN9RUA35522 | C8: 2024 | D8: FORD | E8: ESCAPE | F8: Truck | G8: Retail | H8: BILL WISE'S EXCAVATING INC | I8: Conventional | K8: BILL WISE'S EXCAVATING INC | L8: 944 JOLLYTOWN RD | M8: NEW FREEPORT | N8: PA | O8: 15352-1574 | Q8: 724-451-8175 | T8: 400 | U8: 0 | V8: 0 | W8: 0 | X8: 0 | Y8: 0 | Z8: 0 | AA8: 0 | AB8: 0
A9: 2025-01-02 | B9: 1FMCU9MN7RUA78790 | C9: 2024 | D9: FORD | E9: ESCAPE | F9: Truck | G9: Lease | H9: KWIATKOWSKI,GARY | I9: Conventional | J9: GARY | K9: KWIATKOWSKI | L9: 1333 CLEARVIEW DR | M9: JAMISON | N9: PA | O9: 18929-1149 | Q9: 215-262-4614 | S9: 215-262-4614 | T9: 0 | U9: 0 | V9: 0 | W9: 0 | X9: 0 | Y9: 25 | Z9: 0 | AA9: 0 | AB9: 0
A10: 2025-01-02 | B10: 1FDNF7AN0SDF09472 | C10: 2025 | D10: FORD MEDIUM TRUCKS | E10: F-750 | F10: Truck | G10: Retail | H10: DAIDONE ELECTRIC, INC | I10: Fleet | K10: DAIDONE ELECTRIC, INC | L10: 200 RAYMOND BLVD | M10: NEWARK | N10: NJ | O10: 07105-4608 | P10: NRIBEIRO@DAIDONEELECTRIC.COM | Q10: 973-332-8173 | R10: 973-332-8173 | S10: 973-332-8173 | T10: 0 | U10: 0 | V10: 0 | W10: 0 | X10: 0 | Y10: 0 | Z10: 0 | AA10: 0 | AB10: 0
A11: 2025-01-02 | B11: 1FTFW7LD3SFA04379 | C11: 2025 | D11: FORD | E11: F-150 HYBRID | F11: Truck | G11: Retail | H11: PARK,JOON HYONG | I11: Conventional | J11: JOON | K11: PARK | L11: 419 FORT HILL CIR | M11: FT WASHINGTON | N11: PA | O11: 19034 | P11: JP@JNJFINANCIAL.PRO | Q11: 267-968-8949 | R11: 267-968-8949 | S11: 267-968-8949 | T11: 1000 | U11: 0 | V11: 295 | W11: 0 | X11: 0 | Y11: 726 | Z11: 0 | AA11: 0 | AB11: 0
A12: 2025-01-02 | B12: 1FDNF7AN6SDF09475 | C12: 2025 | D12: FORD MEDIUM TRUCKS | E12: F-750 | F12: Truck | G12: Retail | H12: DAIDONE ELECTRIC, INC | I12: Fleet | K12: DAIDONE ELECTRIC, INC | L12: 200 RAYMOND BLVD | M12: NEWARK | N12: NJ | O12: 07105-4608 | P12: NRIBEIRO@DAIDONEELECTRIC.COM | Q12: 973-332-8173 | R12: 973-332-8173 | S12: 973-332-8173 | T12: 0 | U12: 0 | V12: 0 | W12: 0 | X12: 0 | Y12: 0 | Z12: 0 | AA12: 0 | AB12: 0
A13: 2025-01-02 | B13: 1FT8W3BN9SEC06449 | C13: 2025 | D13: FORD | E13: F-350 | F13: Truck | G13: Retail | H13: BRAVERMAN,CRAIG BRIAN | I13: Conventional | J13: CRAIG | K13: BRAVERMAN | L13: 410 SCHOOL ST PO BOX 1423 | M13: NORTH WALES | N13: PA | O13: 19454 | P13: CBRAVERMAN@COMCAST.NET | Q13: 215-275-0011 | R13: 215-275-0011 | T13: 0 | U13: 0 | V13: 0 | W13: 0 | X13: 0 | Y13: 0 | Z13: 0 | AA13: 0 | AB13: 0
A14: 2025-01-02 | B14: 2FMPK4J94RBB23644 | C14: 2024 | D14: FORD | E14: EDGE | F14: Truck | G14: Retail | H14: CONVILLE,PATRICK F | I14: Conventional | J14: PATRICK | K14: CONVILLE | L14: 1034 WESTON WAY | M14: HATFIELD | N14: PA | O14: 19440-2985 | P14: PATRICK.F.CONVILLE@GMAIL.COM | Q14: 215-840-2124 | R14: 215-840-0115 | S14: 215-840-0115 | T14: 0 | U14: 0 | V14: 0 | W14: 0 | X14: 0 | Y14: 0 | Z14: 0 | AA14: 0 | AB14: 0
A15: 2025-01-02 | B15: 1FMCU9GN2RUA64355 | C15: 2024 | D15: FORD | E15: ESCAPE | F15: Truck | G15: Retail | H15: BILL WISE'S EXCAVATING INC | I15: Conventional | K15: BILL WISE'S EXCAVATING INC | L15: 944 JOLLYTOWN RD | M15: NEW FREEPORT | N15: PA | O15: 15352-1574 | Q15: 724-451-8175 | T15: 600 | U15: 0 | V15: 0 | W15: 0 | X15: 0 | Y15: 0 | Z15: 0 | AA15: 0 | AB15: 0
A16: 2025-01-02 | B16: 1FMWK8HC3SGB00858 | C16: 2025 | D16: FORD | E16: EXP | F16: Truck | G16: Retail | H16: CASTIMORE,RICHARD G | I16: Conventional | J16: RICHARD | K16: CASTIMORE | L16: 103 LINABERRY RD | M16: COLUMBIA | N16: NJ | O16: 07832-2309 | P16: MBCASTIMORE@GMAIL.COM | Q16: 908-459-4360 | S16: 908-619-0140 | T16: 1500 | U16: 0 | V16: 0 | W16: 0 | X16: 0 | Y16: 431 | Z16: 0 | AA16: 0 | AB16: 0
A17: 2025-01-02 | B17: 1FT8W3DM4SEC05536 | C17: 2025 | D17: FORD | E17: F-350 | F17: Truck | G17: Retail | H17: MURPHY IV,WILLIAM HOUSTON | I17: Conventional | J17: WILLIAM | K17: MURPHY | L17: 414 GLENWAY RD | M17: GLENSIDE | N17: PA | O17: 19038-7020 | P17: billy414@aol.com | Q17: 215-778-9074 | T17: 100 | U17: 0 | V17: 0 | W17: 0 | X17: 0 | Y17: 0 | Z17: 0 | AA17: 0 | AB17: 0
A18: 2025-01-02 | B18: 1FMDE7BH1RLB50110 | C18: 2024 | D18: FORD | E18: BRONCO | F18: Truck | G18: Lease | H18: MISCIO,LINDSAY | I18: Conventional | J18: LINDSAY | K18: MISCIO | L18: 4959 JULIE COURT | M18: DOYLESTOWN | N18: PA | O18: 18902 | P18: LINDSAYMISCIO@GMAIL.COM | Q18: 215-850-5776 | S18: 215-771-4646 | T18: 0 | U18: 0 | V18: 0 | W18: 0 | X18: 0 | Y18: 0 | Z18: 0 | AA18: 0 | AB18: 0
A19: 2025-01-02 | B19: 1FMCU9GN7RUB50230 | C19: 2024 | D19: FORD | E19: ESCAPE | F19: Truck | G19: Retail | H19: BILL WISE'S EXCAVATING INC | I19: Conventional | K19: BILL WISE'S EXCAVATING INC | L19: 944 JOLLYTOWN RD | M19: NEW FREEPORT | N19: PA | O19: 15352-1574 | Q19: 724-451-8175 | T19: 600 | U19: 0 | V19: 0 | W19: 0 | X19: 0 | Y19: 0 | Z19: 0 | AA19: 0 | AB19: 0
A20: 2025-01-02 | B20: 1FMUK8KH7SGA37114 | C20: 2025 | D20: FORD | E20: EXPLORER | F20: Truck | G20: Retail | H20: WAHRHAFTIG,JOEL F | I20: Conventional | J20: JOEL | K20: WAHRHAFTIG | L20: 202 SHEPARD LN | M20: CHALFONT | N20: PA | O20: 18914-3569 | P20: JFWTECHIE@GMAIL.COM | Q20: 267-475-5561 | S20: 267-475-5561 | T20: 0 | U20: 0 | V20: 0 | W20: 0 | X20: 0 | Y20: 0 | Z20: 0 | AA20: 0 | AB20: 0
A21: 2025-01-02 | B21: 1FTVW3L71RWG04035 | C21: 2024 | D21: FORD | E21: F-150 | F21: Truck | G21: Retail | H21: RICKENS JR,ALBERT JOHN | I21: Conventional | J21: ALBERT | K21: RICKENS | L21: 725 BRIDGTON PIKE | M21: MANTUA | N21: NJ | O21: 08051 | P21: AJSTOYS63@GMAIL.COM | Q21: 609-238-1679 | R21: 609-238-1679 | S21: 609-238-1679 | T21: 0 | U21: 0 | V21: 0 | W21: 0 | X21: 0 | Y21: 0 | Z21: 0 | AA21: 0 | AB21: 0
A22: 2025-01-02 | B22: 1FTER4PH2RLE73909 | C22: 2024 | D22: FORD | E22: RANGER | F22: Truck | G22: Retail | H22: MATERIAL SOLUTIONS INC | I22: Conventional | K22: MATERIAL SOLUTIONS INC | L22: 28C INDUSTRIAL DR | M22: TRENTON | N22: NJ | O22: 08619-3245 | P22: MUSTANGROG06@ICLOUD.COM | Q22: 215-801-1452 | S22: 215-801-1452 | T22: 0 | U22: 0 | V22: 0 | W22: 0 | X22: 0 | Y22: 0 | Z22: 0 | AA22: 0 | AB22: 0
A23: 2025-01-02 | B23: 1FMUK8DH8SGA36549 | C23: 2025 | D23: FORD | E23: EXPLORER | F23: Truck | G23: Lease | H23: GAMBONE,JOHN MICHAEL | I23: Conventional | J23: JOHN | K23: GAMBONE | L23: 202 RED MAPLE CT | M23: CHALFONT | N23: PA | O23: 18914-4413 | P23: JGAMBONE424@GMAIL.COM | Q23: 215-206-6758 | S23: 215-206-6758 | T23: 0 | U23: 0 | V23: 0 | W23: 0 | X23: 0 | Y23: 431 | Z23: 0 | AA23: 0 | AB23: 0
A24: 2025-01-03 | B24: 1FMUK8KH9SGB01556 | C24: 2025 | D24: FORD | E24: EXP | F24: Truck | G24: Lease | H24: LOLAS II,WILLIAM | I24: Conventional | J24: WILLIAM | K24: LOLAS II | L24: 2030 BEDFORDSHIRE RD | M24: FURLONG | N24: PA | O24: 18925 | P24: BLOLAS@COMCAST.NET | Q24: 215-805-3290 | R24: 215-805-3290 | S24: 215-805-3290 | T24: 0 | U24: 0 | V24: 0 | W24: 0 | X24: 0 | Y24: 0 | Z24: 0 | AA24: 0 | AB24: 0
A25: 2025-01-03 | B25: 1FMDE8BH0RLA90116 | C25: 2024 | D25: FORD | E25: BRONCO | F25: Truck | G25: Retail | H25: WETHERILL,JULIE LYNN | I25: Conventional | J25: JULIE | K25: WETHERILL | L25: 2115 UPPER STUMP RD | M25: FOUNTAINVILLE | N25: PA | O25: 18923 | P25: DKWETHERILL@GMAIL.COM | Q25: 267-429-5700 | S25: 267-429-5700 | T25: 0 | U25: 0 | V25: 0 | W25: 0 | X25: 0 | Y25: 0 | Z25: 0 | AA25: 0 | AB25: 0
A26: 2025-01-04 | B26: 1FMDE2AP4RLA32533 | C26: 2024 | D26: FORD | E26: BRONCO | F26: Truck | G26: Retail | H26: SYLVESTER,JOHN | I26: Conventional | J26: JOHN | K26: SYLVESTER | L26: 1410 BENNER SCHOOL RD | M26: QUAKERTOWN | N26: PA | O26: 18951 | P26: HIPWR308@VERIZON.NET | Q26: 267-372-0641 | R26: 267-372-0641 | T26: 0 | U26: 0 | V26: 0 | W26: 0 | X26: 0 | Y26: 0 | Z26: 0 | AA26: 0 | AB26: 0
A27: 2025-01-04 | B27: 1FMCU9NZ3SUA36883 | C27: 2025 | D27: FORD | E27: ESCAPE | F27: Truck | G27: Retail | H27: ARMAGOST,JOHN ROBERT | I27: Conventional | J27: JOHN | K27: ARMAGOST | L27: 4804 WOODSPRING DR | M27: PIPERSVILLE | N27: PA | O27: 18947-1064 | P27: ARMAGOSTJACK@GMAIL.COM | Q27: 267-337-5854 | S27: 267-337-5854 | T27: 1945 | U27: 0 | V27: 120 | W27: 0 | X27: 0 | Y27: 726 | Z27: 0 | AA27: 0 | AB27: 0
A28: 2025-01-06 | B28: 1FDRF3FN2PEC92687 | C28: 2023 | D28: FORD | E28: F-350 | F28: Truck | G28: Retail | H28: INTEK AUTO LEASING | I28: Fleet | K28: INTEK AUTO LEASING | L28: 152 EAGLE ROCK AVE | M28: ROSELAND | N28: NJ | O28: 07068-1320 | Q28: 973-403-7788 | R28: 973-403-7788 | S28: 484-226-9523 | T28: 0 | U28: 0 | V28: 0 | W28: 0 | X28: 0 | Y28: 0 | Z28: 0 | AA28: 0 | AB28: 0
A29: 2025-01-07 | B29: 1FM5K8AW1SGA86667 | C29: 2025 | D29: FORD | E29: EXPLORER | F29: Truck | G29: Retail | H29: BOROUGH OF CONSHOHOCKEN | I29: Fleet | K29: BOROUGH OF CONSHOHOCKEN | L29: 4000 FAYETTE STREET SUITE 200 | M29: CONSHOHOCKEN | N29: PA | O29: 19428-2187 | P29: PCOSTA@CONSHOCKENPA.GOV | Q29: 610-828-4031 | S29: 610-476-8396 | T29: 0 | U29: 0 | V29: 0 | W29: 0 | X29: 0 | Y29: 0 | Z29: 0 | AA29: 0 | AB29: 0
A30: 2025-01-07 | B30: 1FT8W2BN1REE83522 | C30: 2024 | D30: FORD | E30: F-250 | F30: Truck | G30: Retail | H30: FISHER,SCOTT GORDON | I30: Conventional | J30: SCOTT | K30: FISHER | L30: 105 JANE CHAPMAN DR | M30: NEWTOWN | N30: PA | O30: 18940-3123 | P30: FISHERHARDWARE@AOL.COM | Q30: 215-550-6257 | R30: 215-350-9345 | S30: 215-350-9345 | T30: 0 | U30: 0 | V30: 0 | W30: 0 | X30: 0 | Y30: 431 | Z30: 0 | AA30: 0 | AB30: 0
A31: 2025-01-07 | B31: 1FMEE9BP6RLB14579 | C31: 2024 | D31: FORD | E31: BRONCO | F31: Truck | G31: Retail | H31: FIERABEND,DAVID FREDERICK | I31: Conventional | J31: DAVID | K31: FIERABEND | L31: 6390 FLEECYDALE RD | M31: CARVERSVILLE | N31: PA | O31: 18913 | Q31: 609-240-5262 | S31: 609-240-5262 | T31: 0 | U31: 0 | V31: 0 | W31: 0 | X31: 0 | Y31: 0 | Z31: 0 | AA31: 0 | AB31: 0
A32: 2025-01-07 | B32: 1FMEE2BP4RLB14913 | C32: 2024 | D32: FORD | E32: BRONCO | F32: Truck | G32: Retail | H32: HARRISON,MATTHEW THOMAS | I32: Conventional | J32: MATTHEW | K32: HARRISON | L32: 648 BENNETT LN | M32: PERKASIE | N32: PA | O32: 18944-2609 | P32: HARRISON9128@GMAIL.COM | Q32: 814-574-9800 | R32: 814-574-9800 | S32: 814-574-9800 | T32: 0 | U32: 0 | V32: 0 | W32: 0 | X32: 0 | Y32: 0 | Z32: 0 | AA32: 0 | AB32: 0
A33: 2025-01-07 | B33: 1FDTF4HT8PDA08069 | C33: 2023 | D33: FORD | E33: F-450 | F33: Truck | G33: Retail | H33: BOROUGH OF DANVILLE | I33: Fleet | K33: BOROUGH OF DANVILLE | L33: 463 MILL ST | M33: DANVILLE | N33: PA | O33: 17821-1012 | Q33: 570-275-3091 | T33: 0 | U33: 0 | V33: 0 | W33: 0 | X33: 0 | Y33: 0 | Z33: 0 | AA33: 0 | AB33: 0
A34: 2025-01-08 | B34: 1FDUF5HT8RDA10689 | C34: 2024 | D34: FORD | E34: F-550 | F34: Truck | G34: Lease | H34: C&M WASTE WATER SERVICE LLC | I34: Conventional | K34: C&M WASTE WATER SERVICE LLC | L34: 944 JOLLYTOWN RD | M34: NEW FREEPORT | N34: PA | O34: 15352-1574 | Q34: 724-451-8175 | S34: 412-475-0169 | T34: 1350 | U34: 0 | V34: 0 | W34: 0 | X34: 0 | Y34: 0 | Z34: 0 | AA34: 0 | AB34: 0
A35: 2025-01-08 | B35: 1FTBW1Y89RKA35242 | C35: 2024 | D35: FORD | E35: TRANSIT | F35: Truck | G35: Retail | H35: CLEARVIEW WINDOW CLEANING SERVICES, LLC | I35: Conventional | K35: CLEARVIEW WINDOW CLEANING SERVICES, LLC | L35: 2385 LANGHORNE YARDLEY RD | M35: LANGHORNE | N35: PA | O35: 19047 | P35: BRIAN.WINDOWS@GMAIL.COM | Q35: 215-493-2214 | S35: 215-493-2214 | T35: 0 | U35: 0 | V35: 0 | W35: 0 | X35: 0 | Y35: 0 | Z35: 0 | AA35: 0 | AB35: 0
A36: 2025-01-08 | B36: 1FD9X4HT4REC71423 | C36: 2024 | D36: FORD | E36: F-450 | F36: Truck | G36: Lease | H36: C&M WASTE WATER SERVICE LLC | I36: Conventional | K36: C&M WASTE WATER SERVICE LLC | L36: 944 JOLLYTOWN RD | M36: NEW FREEPORT | N36: PA | O36: 15352-1574 | Q36: 724-451-8175 | S36: 412-475-0169 | T36: 1350 | U36: 0 | V36: 0 | W36: 0 | X36: 0 | Y36: 0 | Z36: 0 | AA36: 0 | AB36: 0
A37: 2025-01-08 | B37: 1FBAX2C82RKB47794 | C37: 2024 | D37: FORD | E37: TRANSIT | F37: Truck | G37: Retail | H37: LUZERNE COUNTY TRANSPORTATION AUTHORITY | I37: Fleet | K37: LUZERNE COUNTY TRANSPORTATION AUTHORITY | L37: 315 NORTHAMPTON ST | M37: KINGSTON | N37: PA | O37: 18704-5423 | Q37: 570-288-9356 | T37: 0 | U37: 0 | V37: 0 | W37: 0 | X37: 0 | Y37: 0 | Z37: 0 | AA37: 0 | AB37: 0
A38: 2025-01-09 | B38: 1FMUK8KH6SGA35466 | C38: 2025 | D38: FORD | E38: EXPLORER | F38: Truck | G38: Retail | H38: BRESLIN,CASEY REBECCA | I38: Conventional | J38: CASEY | K38: BRESLIN | L38: 5004 BIRDIE LN | M38: DOYLESTOWN | N38: PA | O38: 18901 | P38: CASEYRBRESLIN@GMAIL.COM | Q38: 610-888-8517 | R38: 215-847-9006 | S38: 610-888-8517 | T38: 2000 | U38: 0 | V38: 0 | W38: 0 | X38: 0 | Y38: 631 | Z38: 0 | AA38: 0 | AB38: 0
A39: 2025-01-11 | B39: 3FTTW8H3XSRA00602 | C39: 2025 | D39: FORD | E39: MAVERICK | F39: Truck | G39: Retail | H39: PCM CONTRACTING INC | I39: Conventional | K39: PCM CONTRACTING INC | L39: 537 E COUNTY LINE RD | M39: HATBORO | N39: PA | O39: 19040-1217 | Q39: 215-400-1073 | T39: 0 | U39: 0 | V39: 0 | W39: 0 | X39: 0 | Y39: 0 | Z39: 0 | AA39: 0 | AB39: 0
A40: 2025-01-11 | B40: 1FMCU9MN4RUA67908 | C40: 2024 | D40: FORD | E40: ESCAPE | F40: Truck | G40: Lease | H40: HAINES,WAYNE G | I40: Conventional | J40: WAYNE | K40: HAINES | L40: 83 ARISTOTLE WAY | M40: CRANBURY | N40: NJ | O40: 08512 | P40: WGHAINES60@VERIZON.NET | Q40: 609-448-3019 | R40: 215-787-2234 | S40: 347-413-3051 | T40: 0 | U40: 0 | V40: 0 | W40: 0 | X40: 0 | Y40: 790 | Z40: 0 | AA40: 0 | AB40: 0
...

Sheet Sheet1
A3: DOYLESTOWN | B3: 852
A4: PHILADELPHIA | B4: 341 | F4: ALLENTOWN
A5: PERKASIE | B5: 244 | F5: AMBLER
A6: CHALFONT | B6: 224 | F6: BENSALEM
A7: WARMINSTER | B7: 211 | F7: BLUE BELL
A8: WARRINGTON | B8: 206 | F8: BRISTOL
A9: PIPERSVILLE | B9: 174 | F9: CHALFONT
A10: NEW HOPE | B10: 157 | F10: DOYLESTOWN
A11: NEWTOWN | B11: 149 | F11: EASTON
A12: LANSDALE | B12: 125 | F12: FURLONG
A13: QUAKERTOWN | B13: 124 | F13: HATBORO
A14: FURLONG | B14: 107 | F14: HATFIELD
A15: JAMISON | B15: 97 | F15: HOLLAND
... A36: RICHBORO | B36: 51 | F36: WARRINGTON
F37: YARDLEY
A38: WEST CHESTER | B38: 48
A39: CHERRY HILL | B39: 47
A40: BETHLEHEM | B40: 46
A41: HARLEYSVILLE | B41: 45
A42: WORCESTER | B42: 44
A43: SPARKS | B43: 43
A44: OTTSVILLE | B44: 38
A45: IVYLAND | B45: 38
A46: ST. LOUIS | B46: 38
A47: TELFORD | B47: 37
A48: WILLOW GROVE | B48: 36
A49: CONSHOHOCKEN | B49: 35
... A1126: LEDERACH | B1126: 1

Sheet Call List
B2: NAME | C2: COUNT | D2: Type | E2: Street | F2: City | G2: State | H2: Zip Code | I2: Email | J2: Cell Phone
B3: PRINCETON UNIVERSITY | C3: 58 | D3: =VLOOKUP($B3,'F&I Log'!$H$3:$I$8977,2,FALSE) -> Fleet | E3: =(VLOOKUP($B3,'F&I Log'!$H$3:$S$8977,5,FALSE)) -> PO BOX 33 | F3: =IFERROR(VLOOKUP($B3,'F&I Log'!$H$3:$S$8977,6,FALSE),"--") -> PRINCETON | G3: =IFERROR(VLOOKUP($B3,'F&I Log'!$H$3:$S$8977,7,FALSE),"--") -> NJ | H3: =IFERROR(VLOOKUP($B3,'F&I Log'!$H$3:$S$8977,8,FALSE),"--") -> 08543-0033 | I3: =IFERROR(VLOOKUP($B3,'F&I Log'!$H$3:$S$8977,9,FALSE),"--") -> MH25@PRINCETON.EDU | J3: =IFERROR(VLOOKUP($B3,'F&I Log'!$H$3:$S$8977,10,FALSE),"--") -> 609-947-5852
B4: JAMES D MORRISSEY INC | C4: 40 | D4: =VLOOKUP($B4,'F&I Log'!$H$3:$I$8977,2,FALSE) -> Fleet | E4: =(VLOOKUP($B4,'F&I Log'!$H$3:$S$8977,5,FALSE)) -> 9119 FRANKFORD AVE | F4: =IFERROR(VLOOKUP($B4,'F&I Log'!$H$3:$S$8977,6,FALSE),"--") -> PHILADELPHIA | G4: =IFERROR(VLOOKUP($B4,'F&I Log'!$H$3:$S$8977,7,FALSE),"--") -> PA | H4: =IFERROR(VLOOKUP($B4,'F&I Log'!$H$3:$S$8977,8,FALSE),"--") -> 19114-2884 | I4: =IFERROR(VLOOKUP($B4,'F&I Log'!$H$3:$S$8977,9,FALSE),"--") -> CA8186@AOL.COM | J4: =IFERROR(VLOOKUP($B4,'F&I Log'!$H$3:$S$8977,10,FALSE),"--") -> 215-539-3505
B5: GLESBY MARKS LTD | C5: 35 | D5: =VLOOKUP($B5,'F&I Log'!$H$3:$I$8977,2,FALSE) -> Fleet | E5: =(VLOOKUP($B5,'F&I Log'!$H$3:$S$8977,5,FALSE)) -> PO BOX 4875 | F5: =IFERROR(VLOOKUP($B5,'F&I Log'!$H$3:$S$8977,6,FALSE),"--") -> HOUSTON | G5: =IFERROR(VLOOKUP($B5,'F&I Log'!$H$3:$S$8977,7,FALSE),"--") -> TX | H5: =IFERROR(VLOOKUP($B5,'F&I Log'!$H$3:$S$8977,8,FALSE),"--") -> 77210 | I5: =IFERROR(VLOOKUP($B5,'F&I Log'!$H$3:$S$8977,9,FALSE),"--") -> KCASEY@4DONNELLYS.COM | J5: =IFERROR(VLOOKUP($B5,'F&I Log'!$H$3:$S$8977,10,FALSE),"--") -> 713-366-8223
B6: R & S HARDSCAPING, LLC | C6: 28 | D6: =VLOOKUP($B6,'F&I Log'!$H$3:$I$8977,2,FALSE) -> Conventional | E6: =(VLOOKUP($B6,'F&I Log'!$H$3:$S$8977,5,FALSE)) -> 765 SANATOGA ROAD | F6: =IFERROR(VLOOKUP($B6,'F&I Log'!$H$3:$S$8977,6,FALSE),"--") -> POTTSTOWN | G6: =IFERROR(VLOOKUP($B6,'F&I Log'!$H$3:$S$8977,7,FALSE),"--") -> PA | H6: =IFERROR(VLOOKUP($B6,'F&I Log'!$H$3:$S$8977,8,FALSE),"--") -> 19465 | I6: =IFERROR(VLOOKUP($B6,'F&I Log'!$H$3:$S$8977,9,FALSE),"--") | J6: =IFERROR(VLOOKUP($B6,'F&I Log'!$H$3:$S$8977,10,FALSE),"--") -> 484-624-2810
B7: DONLEN TRUST | C7: 21 | D7: =VLOOKUP($B7,'F&I Log'!$H$3:$I$8977,2,FALSE) -> Fleet | E7: =(VLOOKUP($B7,'F&I Log'!$H$3:$S$8977,5,FALSE)) -> 666 GARLAND PLACE | F7: =IFERROR(VLOOKUP($B7,'F&I Log'!$H$3:$S$8977,6,FALSE),"--") -> DES PLAINES | G7: =IFERROR(VLOOKUP($B7,'F&I Log'!$H$3:$S$8977,7,FALSE),"--") -> IL | H7: =IFERROR(VLOOKUP($B7,'F&I Log'!$H$3:$S$8977,8,FALSE),"--") -> 60016 | I7: =IFERROR(VLOOKUP($B7,'F&I Log'!$H$3:$S$8977,9,FALSE),"--") -> BTAYLOR@DONLEN.COM | J7: =IFERROR(VLOOKUP($B7,'F&I Log'!$H$3:$S$8977,10,FALSE),"--") -> 847-412-4961
B8: THE SUPREME COURT OF THE UNITED STATES | C8: 21 | D8: =VLOOKUP($B8,'F&I Log'!$H$3:$I$8977,2,FALSE) -> Fleet | E8: =(VLOOKUP($B8,'F&I Log'!$H$3:$S$8977,5,FALSE)) -> 1 1ST ST NE | F8: =IFERROR(VLOOKUP($B8,'F&I Log'!$H$3:$S$8977,6,FALSE),"--") -> WASHINGTON | G8: =IFERROR(VLOOKUP($B8,'F&I Log'!$H$3:$S$8977,7,FALSE),"--") -> DC | H8: =IFERROR(VLOOKUP($B8,'F&I Log'!$H$3:$S$8977,8,FALSE),"--") -> 20543-0002 | I8: =IFERROR(VLOOKUP($B8,'F&I Log'!$H$3:$S$8977,9,FALSE),"--") | J8: =IFERROR(VLOOKUP($B8,'F&I Log'!$H$3:$S$8977,10,FALSE),"--")
B9: FIFTH THIRD BANK NATIONAL ASSOC | C9: 20 | D9: =VLOOKUP($B9,'F&I Log'!$H$3:$I$8977,2,FALSE) -> Fleet | E9: =(VLOOKUP($B9,'F&I Log'!$H$3:$S$8977,5,FALSE)) -> 38 FOUNTAIN SQUARE PLZ | F9: =IFERROR(VLOOKUP($B9,'F&I Log'!$H$3:$S$8977,6,FALSE),"--") -> CINCINNATI | G9: =IFERROR(VLOOKUP($B9,'F&I Log'!$H$3:$S$8977,7,FALSE),"--") -> OH | H9: =IFERROR(VLOOKUP($B9,'F&I Log'!$H$3:$S$8977,8,FALSE),"--") -> 45202-3102 | I9: =IFERROR(VLOOKUP($B9,'F&I Log'!$H$3:$S$8977,9,FALSE),"--") -> SEAN.HOLDEN@53.COM | J9: =IFERROR(VLOOKUP($B9,'F&I Log'!$H$3:$S$8977,10,FALSE),"--") -> 443-798-6520
B10: PRINCIPLE ENTERPRISES, LLC | C10: 17 | D10: =VLOOKUP($B10,'F&I Log'!$H$3:$I$8977,2,FALSE) -> Conventional | E10: =(VLOOKUP($B10,'F&I Log'!$H$3:$S$8977,5,FALSE)) -> PO BOX 177 | F10: =IFERROR(VLOOKUP($B10,'F&I Log'!$H$3:$S$8977,6,FALSE),"--") -> CANTON | G10: =IFERROR(VLOOKUP($B10,'F&I Log'!$H$3:$S$8977,7,FALSE),"--") -> PA | H10: =IFERROR(VLOOKUP($B10,'F&I Log'!$H$3:$S$8977,8,FALSE),"--") -> 17724-0177 | I10: =IFERROR(VLOOKUP($B10,'F&I Log'!$H$3:$S$8977,9,FALSE),"--") -> mpapalia@principleenterprises.com | J10: =IFERROR(VLOOKUP($B10,'F&I Log'!$H$3:$S$8977,10,FALSE),"--") -> 570-250-5101
B11: BBC REAL ESTATE HOLDING CO LLC | C11: 16 | D11: =VLOOKUP($B11,'F&I Log'!$H$3:$I$8977,2,FALSE) -> Fleet | E11: =(VLOOKUP($B11,'F&I Log'!$H$3:$S$8977,5,FALSE)) -> 2701 BARTRAM RD | F11: =IFERROR(VLOOKUP($B11,'F&I Log'!$H$3:$S$8977,6,FALSE),"--") -> BRISTOL | G11: =IFERROR(VLOOKUP($B11,'F&I Log'!$H$3:$S$8977,7,FALSE),"--") -> PA | H11: =IFERROR(VLOOKUP($B11,'F&I Log'!$H$3:$S$8977,8,FALSE),"--") -> 19007 | I11: =IFERROR(VLOOKUP($B11,'F&I Log'!$H$3:$S$8977,9,FALSE),"--") | J11: =IFERROR(VLOOKUP($B11,'F&I Log'!$H$3:$S$8977,10,FALSE),"--") -> 215-788-2700
B12: D L PETERSON TRUST | C12: 15 | D12: =VLOOKUP($B12,'F&I Log'!$H$3:$I$8977,2,FALSE) -> Fleet | E12: =(VLOOKUP($B12,'F&I Log'!$H$3:$S$8977,5,FALSE)) -> 940 RIDGEBROOK RD | F12: =IFERROR(VLOOKUP($B12,'F&I Log'!$H$3:$S$8977,6,FALSE),"--") -> SPARKS | G12: =IFERROR(VLOOKUP($B12,'F&I Log'!$H$3:$S$8977,7,FALSE),"--") -> MD | H12: =IFERROR(VLOOKUP($B12,'F&I Log'!$H$3:$S$8977,8,FALSE),"--") -> 21152 | I12: =IFERROR(VLOOKUP($B12,'F&I Log'!$H$3:$S$8977,9,FALSE),"--") | J12: =IFERROR(VLOOKUP($B12,'F&I Log'!$H$3:$S$8977,10,FALSE),"--") -> 410-771-2203
B13: ENTERPRISE FM TRUST LSR | C13: 14 | D13: =VLOOKUP($B13,'F&I Log'!$H$3:$I$8977,2,FALSE) -> Fleet | E13: =(VLOOKUP($B13,'F&I Log'!$H$3:$S$8977,5,FALSE)) -> 2281 BALL DRIVE | F13: =IFERROR(VLOOKUP($B13,'F&I Log'!$H$3:$S$8977,6,FALSE),"--") -> ST LOUIS | G13: =IFERROR(VLOOKUP($B13,'F&I Log'!$H$3:$S$8977,7,FALSE),"--") -> MO | H13: =IFERROR(VLOOKUP($B13,'F&I Log'!$H$3:$S$8977,8,FALSE),"--") -> 63146 | I13: =IFERROR(VLOOKUP($B13,'F&I Log'!$H$3:$S$8977,9,FALSE),"--") | J13: =IFERROR(VLOOKUP($B13,'F&I Log'!$H$3:$S$8977,10,FALSE),"--")
B14: BILL WISE'S EXCAVATING INC | C14: 12 | D14: =VLOOKUP($B14,'F&I Log'!$H$3:$I$8977,2,FALSE) -> Conventional | E14: =(VLOOKUP($B14,'F&I Log'!$H$3:$S$8977,5,FALSE)) -> 944 JOLLYTOWN RD | F14: =IFERROR(VLOOKUP($B14,'F&I Log'!$H$3:$S$8977,6,FALSE),"--") -> NEW FREEPORT | G14: =IFERROR(VLOOKUP($B14,'F&I Log'!$H$3:$S$8977,7,FALSE),"--") -> PA | H14: =IFERROR(VLOOKUP($B14,'F&I Log'!$H$3:$S$8977,8,FALSE),"--") -> 15352-1574 | I14: =IFERROR(VLOOKUP($B14,'F&I Log'!$H$3:$S$8977,9,FALSE),"--") | J14: =IFERROR(VLOOKUP($B14,'F&I Log'!$H$3:$S$8977,10,FALSE),"--") -> 724-451-8175
... B6246: MERRITT,KENNETH CHARLES | C6246: 1 | D6246: =VLOOKUP($B6246,'F&I Log'!$H$3:$I$8977,2,FALSE) -> Conventional | E6246: =(VLOOKUP($B6246,'F&I Log'!$H$3:$S$8977,5,FALSE)) -> 83 PATRIOT DR | F6246: =IFERROR(VLOOKUP($B6246,'F&I Log'!$H$3:$S$8977,6,FALSE),"--") -> CHALFONT | G6246: =IFERROR(VLOOKUP($B6246,'F&I Log'!$H$3:$S$8977,7,FALSE),"--") -> PA | H6246: =IFERROR(VLOOKUP($B6246,'F&I Log'!$H$3:$S$8977,8,FALSE),"--") -> 18914-2953 | I6246: =IFERROR(VLOOKUP($B6246,'F&I Log'!$H$3:$S$8977,9,FALSE),"--") -> KMERRITT6958@GMAIL.COM | J6246: =IFERROR(VLOOKUP($B6246,'F&I Log'!$H$3:$S$8977,10,FALSE),"--") -> 215-997-7517

Sheet Sheet2
A1: VIN | B1: Year | C1: Make | D1: Model | E1: Vehicle Type | F1: Contract Type | G1: Customer | H1: Sale Type | I1: Address1 | J1: City | K1: State | L1: Zip | M1: PHONE
A2: 1FMUK8KH9SGA60104 | B2: 2025 | C2: FORD | D2: EXPLORER | E2: Truck | F2: Retail | G2: HAYES,DEBORAH | H2: Conventional | I2: 106 GERTRUDE DR | J2: CHALFONT | K2: PA | L2: 18914 | M2: 215-272-2654
A3: 1FMUK8DH1SGA43276 | B3: 2025 | C3: FORD | D3: EXPLORER | E3: Truck | F3: Retail | G3: BASZNIANIN,DARIUSZ | H3: Conventional | I3: 1469 TARLETON PL | J3: WARMINSTER | K3: PA | L3: 18974 | M3: 215-403-1124
A4: 3FMTK3SU8RMA43287 | B4: 2024 | C4: FORD | D4: MUSTME | E4: Truck | F4: Retail | G4: POIRIER,LUC STEPHANE | H4: Conventional | I4: 113 TELEGRAPH RD | J4: PERKASIE | K4: PA | L4: 18944-2644 | M4: 612-434-4486
A5: 1FMCU9MN7RUA78790 | B5: 2024 | C5: FORD | D5: ESCAPE | E5: Truck | F5: Lease | G5: KWIATKOWSKI,GARY | H5: Conventional | I5: 1333 CLEARVIEW DR | J5: JAMISON | K5: PA | L5: 18929-1149 | M5: 215-262-4614
A6: 1FT8W3BN9SEC06449 | B6: 2025 | C6: FORD | D6: F-350 | E6: Truck | F6: Retail | G6: BRAVERMAN,CRAIG BRIAN | H6: Conventional | I6: 410 SCHOOL ST PO BOX 1423 | J6: NORTH WALES | K6: PA | L6: 19454 | M6: 215-275-0011
A7: 2FMPK4J94RBB23644 | B7: 2024 | C7: FORD | D7: EDGE | E7: Truck | F7: Retail | G7: CONVILLE,PATRICK F | H7: Conventional | I7: 1034 WESTON WAY | J7: HATFIELD | K7: PA | L7: 19440-2985 | M7: 215-840-0115
A8: 1FT8W3DM4SEC05536 | B8: 2025 | C8: FORD | D8: F-350 | E8: Truck | F8: Retail | G8: MURPHY IV,WILLIAM HOUSTON | H8: Conventional | I8: 414 GLENWAY RD | J8: GLENSIDE | K8: PA | L8: 19038-7020 | M8: 215-778-9074
A9: 1FMDE7BH1RLB50110 | B9: 2024 | C9: FORD | D9: BRONCO | E9: Truck | F9: Lease | G9: MISCIO,LINDSAY | H9: Conventional | I9: 4959 JULIE COURT | J9: DOYLESTOWN | K9: PA | L9: 18902 | M9: 215-771-4646
A10: 1FMUK8KH7SGA37114 | B10: 2025 | C10: FORD | D10: EXPLORER | E10: Truck | F10: Retail | G10: WAHRHAFTIG,JOEL F | H10: Conventional | I10: 202 SHEPARD LN | J10: CHALFONT | K10: PA | L10: 18914-3569 | M10: 267-475-5561
A11: 1FMUK8DH8SGA36549 | B11: 2025 | C11: FORD | D11: EXPLORER | E11: Truck | F11: Lease | G11: GAMBONE,JOHN MICHAEL | H11: Conventional | I11: 202 RED MAPLE CT | J11: CHALFONT | K11: PA | L11: 18914-4413 | M11: 215-206-6758
A12: 1FMUK8KH9SGB01556 | B12: 2025 | C12: FORD | D12: EXP | E12: Truck | F12: Lease | G12: LOLAS II,WILLIAM | H12: Conventional | I12: 2030 BEDFORDSHIRE RD | J12: FURLONG | K12: PA | L12: 18925 | M12: 215-805-3290
... A295: 1FTBR2C85SKA60181 | B295: 2025 | C295: FORD | D295: TRANSIT | E295: Truck | F295: Retail | G295: PERRIWINKLE INC | H295: Conventional | I295: 1605 W BRISTOL RD | J295: WARMINSTER | K295: PA | L295: 18974-1007 | M295: 267-229-2785
A296: 3FTTW8J98RRB60082 | B296: 2024 | C296: FORD | D296: MAVERICK | E296: Truck | F296: Retail | G296: KOZI GROUP LLC DBA WHITAKER ROOFING AND | H296: Conventional | I296: 1715 W GREEN ST | J296: ALLENTOWN | K296: PA | L296: 18104-4109
A297: 3FTTW8J95RRB72397 | B297: 2024 | C297: FORD | D297: MAVERICK | E297: Truck | F297: Retail | G297: KOZI CONTRACTING LLC | H297: Conventional | I297: 1850 BUTLER ST | J297: EASTON | K297: PA | L297: 18042-4626 | M297: 484-627-1364
A298: 3FTTW8J97RRB81070 | B298: 2024 | C298: FORD | D298: MAVERICK | E298: Truck | F298: Retail | G298: KOZI CONTRACTING LLC | H298: Conventional | I298: 1850 BUTLER ST | J298: EASTON | K298: PA | L298: 18042-4626 | M298: 484-627-1364
A299: 1FTBF2BA8SED47753 | B299: 2025 | C299: FORD | D299: F-250 | E299: Truck | F299: Retail | G299: BIAMONTE,ANTHONY | H299: Conventional | I299: 4096 UPPER MOUNTAIN RD | J299: FURLONG | K299: PA | L299: 18925 | M299: 215-813-2764
A300: 1FMCU0E11SUA46558 | B300: 2025 | C300: FORD | D300: ESCAPE | E300: Truck | F300: Retail | G300: SHUTE,JAMES | H300: Conventional | I300: 3706 JACOB STOUT RD | J300: DOYLESTOWN | K300: PA | L300: 18902-9110 | M300: 215-262-4133
A301: 1FMWK8HC5SGB94144 | B301: 2025 | C301: FORD | D301: EXPLORER | E301: Truck | F301: Retail | G301: ADAIR,JAMES RYAN | H301: Conventional | I301: 5500 JILLIAN WAY | J301: PIPERSVILLE | K301: PA | L301: 18947-1189 | M301: 484-894-5147
A302: 1FMWK8GC1SGB96118 | B302: 2025 | C302: FORD | D302: EXP | E302: Truck | F302: Retail | G302: DALESSIO,REBECKA LEE | H302: Conventional | I302: 1008 TELEGRAPH RD | J302: PERKASIE | K302: PA | L302: 18944-2432 | M302: 215-275-8420
A303: 1FD0W5HN1SED06315 | B303: 2025 | C303: FORD | D303: F-550 | E303: Truck | F303: Retail | G303: A & Y LANDSCAPING & TREE SERVICES, LLC. | H303: Conventional | I303: 3240 BRISTOL RD | J303: CHALFONT | K303: PA | L303: 18914-3443 | M303: 908-616-6468
A304: 1FTFW1L51RKF00322 | B304: 2024 | C304: FORD | D304: F-150 | E304: Truck | F304: Retail | G304: PLUMSTEADVILLE VOLUNTEER FIRE CO. | H304: Fleet | I304: PO BOX 405 | J304: PLUMSTEADVLLE | K304: PA | L304: 18949-0405 | M304: 215-783-6875
A305: 1FMUK8DH0SGA64586 | B305: 2025 | C305: FORD | D305: EXPLORER | E305: Truck | F305: Retail | G305: GREENE,SUZANNE E | H305: Conventional | I305: 323 ROCKY CT W | J305: CHALFONT | K305: PA | L305: 18914 | M305: 203-451-4152
A306: 1FMUK8DH4SGA64235 | B306: 2025 | C306: FORD | D306: EXPLORER | E306: Truck | F306: Retail | G306: MARTIN,DONNA JEAN | H306: Conventional | I306: 1408 MISSION RD | J306: QUAKERTOWN | K306: PA | L306: 18951-5630 | M306: 215-262-3777
A307: 1FMWK8GC6SGC19327 | B307: 2025 | C307: FORD | D307: EXPLORER | E307: Truck | F307: Lease | G307: SISLER,GARY LEE | H307: Conventional | I307: 1067 BRIDGETON HILL RD | J307: UPPR BLCK EDY | K307: PA | L307: 18972-9435 | M307: 267-377-7374
A308: 54DK6S1F3SSA02661 | B308: 2025 | C308: ISUZU | D308: FTR | E308: Truck | F308: Retail | G308: FRED BEANS PARTS INC | H308: Fleet | I308: 131 DOYLE ST | J308: DOYLESTOWN | K308: PA | L308: 18901-3701 | M308: 215-348-0202
... A337: 1FTFW6LDXSFB11763 | B337: 2025 | C337: FORD | D337: F-150 HYBRID | E337: Truck | F337: Lease | G337: MCALISTER,WILLIAM P | H337: Conventional | I337: 7 CASEY CT | J337: NEWTOWN | K337: PA | L337: 18940 | M337: 267-574-4910
A338: 1FTER4LR2SLE20034 | B338: 2025 | C338: FORD | D338: RANGER | E338: Truck | F338: Retail | G338: YOUNG,CHARLES WILLIAM | H338: Conventional | I338: 19 S LINCOLN AVE | J338: NEWTOWN | K338: PA | L338: 18940-2158
A339: 1FTFW7LD4SFB18777 | B339: 2025 | C339: FORD | D339: F-150 HYBRID | E339: Truck | F339: Lease | G339: SANTURNO LLC | H339: Conventional | I339: 810 GREEN ST | J339: LANSDALE | K339: PA | L339: 19446-5221 | M339: 215-692-7067
A340: 1FT6W5L70SWG16229 | B340: 2025 | C340: FORD | D340: F-150 | E340: Truck | F340: Retail | G340: KELER,CYNTHIA A | H340: Conventional | I340: 198 CAFFERTY RD | J340: PIPERSVILLE | K340: PA | L340: 18947-1613 | M340: 610-357-6570
A341: 1FDXE4FN9TDD03135 | B341: 2026 | C341: FORD | D341: E450 | E341: Truck | F341: Retail | G341: PRINCETON UNIVERSITY | H341: Fleet | I341: PO BOX 33 | J341: PRINCETON | K341: NJ | L341: 08543-0033 | M341: 609-258-5033
A342: 3FMCR9BN1SRE60816 | B342: 2025 | C342: FORD | D342: BRONCO SPORT | E342: Truck | F342: Retail | G342: ACKER,PAMELA MARIE | H342: Conventional | I342: 305 NOTTINGHAM PL | J342: CHALFONT | K342: PA | L342: 18914-2454 | M342: 973-204-5392
A343: 3FMCR9CN4SRE54037 | B343: 2025 | C343: FORD | D343: BRONCO SPORT | E343: Truck | F343: Retail | G343: ROLAND,NICHOLAS MICHAEL | H343: Conventional | I343: 333 N BROAD ST APT 1419 | J343: DOYLESTOWN | K343: PA | L343: 18901-3543 | M343: 858-231-0614
A344: 1FTFW5LD0SFB24161 | B344: 2025 | C344: FORD | D344: F-150 HYBRID | E344: Truck | F344: Retail | G344: BALAAM,STEPHEN JOHN | H344: Conventional | I344: 107 BEAUMONT DR | J344: NEWTOWN | K344: PA | L344: 18940-2525 | M344: 267-688-5815
A345: 1FTYE1C8XRKA76919 | B345: 2024 | C345: FORD | D345: TRANSIT | E345: Truck | F345: Retail | G345: TILGHMAN BUILDERS, INC. | H345: Conventional | I345: 263 S YORK RD | J345: HATBORO | K345: PA | L345: 19040-3427 | M345: 267-220-0758
A346: 1FMCU9GN6SUA34698 | B346: 2025 | C346: FORD | D346: ESCAPE | E346: Truck | F346: Retail | G346: EDGAR,FRANK T | H346: Conventional | I346: 1380 SCHOOL HOUSE LN | J346: JAMISON | K346: PA | L346: 18929-1153 | M346: 215-840-1513
A347: 3FMCR9BN8SRE61008 | B347: 2025 | C347: FORD | D347: BRONCO SPORT | E347: Truck | F347: Retail | G347: LYLE,HEATHER LYNN | H347: Conventional | I347: 13 LIBERTY PL | J347: DOYLESTOWN | K347: PA | L347: 18901-2255 | M347: 267-242-5387
A348: 3FMTK4SX9SMA17383 | B348: 2025 | C348: FORD | D348: MUSTME | E348: Truck | F348: Lease | G348: KIRBERGER,STEVEN PAUL | H348: Conventional | I348: 19 FOXTAIL LN | J348: DOYLESTOWN | K348: PA | L348: 18901-2352 | M348: 317-900-2601
A349: 1FTYE1C85RKB22107 | B349: 2024 | C349: FORD | D349: TRANSIT | E349: Truck | F349: Retail | G349: FRED BEANS PARTS INC | H349: Fleet | I349: 131 DOYLE ST | J349: DOYLESTOWN | K349: PA | L349: 18901-3701 | M349: 215-348-0202
A350: 3FTTW8JA7SRA34506 | B350: 2025 | C350: FORD | D350: MAVERICK | E350: Truck | F350: Retail | G350: VEIT,GEORGE FRANCIS | H350: Conventional | I350: 367 STOOPVILLE RD | J350: NEWTOWN | K350: PA | L350: 18940 | M350: 215-375-5017
...
